Workbook

Sheet Control Panel
A1: ORCL Eight-Quarter Model — Control Panel
A2: Gate 10 minimal build — 2026-07-21. Scenario ranges per D-020 (Gate 8, ratified); driver mechanics per Gate 7 (11_Analysis/forecast/GATE7_FORECAST_DRIVER_DESIGN.md).
A4: Scenario selector
A5: Selected scenario | B5: Base | C5: Choose Bear / Base / Bull — drives every scenario-switched cell in the model
A7: Valuation-date selector (informational, Gate 13 uses this)
A8: Selected valuation date | B8: FY27 Q1 (2026-09-10)
A10: Key model references
A11: Historical dataset | B11: 10_Working_Data/raw_extractions/orcl_historical_quarterly_full.csv (Gate 6, verified zero discrepancies)
A12: EBITDA definition | B12: D-014, ratified — GAAP operating income + CF depreciation + amortization of intangibles, no SBC add-back
A13: Scenario ranges | B13: D-020, ratified (Gate 8) — see 'Scenario Assumptions' tab
A14: Driver mechanics | B14: 11_Analysis/forecast/GATE7_FORECAST_DRIVER_DESIGN.md (Gate 7)
A15: Comps methodology | B15: D-021, ratified (Gate 9) — EV/NTM EBITDA primary; multiples NOT yet assigned, pending Q-08/C-09
A17: Scope note
A18: This is a MINIMAL build (Gate 10): historical actuals, revenue-stream forecast with scenario switching, top-down margin/EBITDA, and integrity checks. Debt/lease/ATM-dilution mechanics, the capacity index (D-019), and per-share valuation output are Gate 12 (full build) / Gate 13 (valuation) scope — not built here.

Sheet Historical Actuals
A1: Historical Actuals — FY2025 Q1 through FY2026 Q4
A2: Source: orcl_historical_quarterly_full.csv / _full_provenance.csv (Gate 6, cross-document verified, zero discrepancies). USD millions unless noted.
A4: Field (USD $mm) | B4: FY25_Q1 | C4: FY25_Q2 | D4: FY25_Q3 | E4: FY25_Q4 | F4: FY26_Q1 | G4: FY26_Q2 | H4: FY26_Q3 | I4: FY26_Q4 | K4: FY2025 | L4: FY2026
A5: REV_310 — OCI revenue | B5: 2154 | C5: 2434 | D5: 2652 | E5: 2995 | F5: 3347 | G5: 4079 | H5: 4888 | I5: 5787 | K5: =SUM(B5:E5) | L5: =SUM(F5:I5)
A6: REV_320 — Cloud applications revenue | B6: 3469 | C6: 3503 | D6: 3558 | E6: 3742 | F6: 3839 | G6: 3898 | H6: 4026 | I6: 4126 | K6: =SUM(B6:E6) | L6: =SUM(F6:I6)
A7: REV_330 — Software support revenue | B7: 4896 | C7: 4869 | D7: 4797 | E7: 4961 | F7: 4955 | G7: 4938 | H7: 4969 | I7: 4943 | K7: =SUM(B7:E7) | L7: =SUM(F7:I7)
A8: REV_340 — Software license revenue | B8: 870 | C8: 1195 | D8: 1129 | E8: 2007 | F8: 766 | G8: 939 | H8: 1150 | I8: 1881 | K8: =SUM(B8:E8) | L8: =SUM(F8:I8)
A9: REV_350 — Hardware revenue | B9: 655 | C9: 728 | D9: 703 | E9: 850 | F9: 670 | G9: 776 | H9: 714 | I9: 924 | K9: =SUM(B9:E9) | L9: =SUM(F9:I9)
A10: REV_360 — Services revenue | B10: 1263 | C10: 1330 | D10: 1291 | E10: 1348 | F10: 1349 | G10: 1428 | H10: 1443 | I10: 1523 | K10: =SUM(B10:E10) | L10: =SUM(F10:I10)
A11: REV_370 — Total revenue (sum of six streams) | B11: =SUM(B5:B10) | C11: =SUM(C5:C10) | D11: =SUM(D5:D10) | E11: =SUM(E5:E10) | F11: =SUM(F5:F10) | G11: =SUM(G5:G10) | H11: =SUM(H5:H10) | I11: =SUM(I5:I10) | K11: =SUM(K5:K10) | L11: =SUM(L5:L10)
A13: Supplemental P&L (for margin/EBITDA reference)
A14: COGS_050 — Gross profit (GAAP, calculated) | B14: 9401 | C14: 9974 | D14: 9935 | E14: 11163 | F14: 10042 | G14: 10704 | H14: 11098 | I14: 12512 | K14: =SUM(B14:E14) | L14: =SUM(F14:I14)
A15: PROF_010 — GAAP operating income | B15: 3991 | C15: 4220 | D15: 4358 | E15: 5109 | F15: 4277 | G15: 4731 | H15: 5464 | I15: 6133 | K15: =SUM(B15:E15) | L15: =SUM(F15:I15)
A16: PROF_030 — Non-GAAP operating income | B16: 5708 | C16: 6096 | D16: 6195 | E16: 7035 | F16: 6236 | G16: 6721 | H16: 7378 | I16: 8590 | K16: =SUM(B16:E16) | L16: =SUM(F16:I16)
A17: PROF_160 — EBITDA (D-014 definition, ratified) | B17: 5439 | C17: 5719 | D17: 5909 | E17: 6805 | F17: 6048 | G17: 6842 | H17: 8030 | I17: 8980 | K17: =SUM(B17:E17) | L17: =SUM(F17:I17)
A19: GAAP gross margin % (=Gross profit / Total revenue) | B19: =B14/B11 | C19: =C14/C11 | D19: =D14/D11 | E19: =E14/E11 | F19: =F14/F11 | G19: =G14/G11 | H19: =H14/H11 | I19: =I14/I11
A20: GAAP operating margin % (=Op income / Total revenue) | B20: =B15/B11 | C20: =C15/C11 | D20: =D15/D11 | E20: =E15/E11 | F20: =F15/F11 | G20: =G15/G11 | H20: =H15/H11 | I20: =I15/I11
A21: Non-GAAP operating margin % (=Non-GAAP op income / Total revenue) | B21: =B16/B11 | C21: =C16/C11 | D21: =D16/D11 | E21: =E16/E11 | F21: =F16/F11 | G21: =G16/G11 | H21: =H16/H11 | I21: =I16/I11
A23: GAAP/non-GAAP bridge components (for CHECK_090)
A24: OPEX_040 — Amortization of intangible assets | B24: 624 | C24: 591 | D24: 548 | E24: 544 | F24: 420 | G24: 407 | H24: 413 | I24: 431
A25: OPEX_070 — Stock-based compensation (total) | B25: 1007 | C25: 1169 | D25: 1198 | E25: 1299 | F25: 1124 | G25: 1156 | H25: 1328 | I25: 1203
A26: Acquisition-related + restructuring (combined; OPEX_050+060, or OPEX_065 where combined-caption) | B26: 86 | C26: 115 | D26: 91 | E26: 83 | F26: 415 | G26: 427 | H26: 173 | I26: 823
A28: Debt, cash & lease anchors (for Debt/Leases/Cash tab)
A29: DEBT_030 — Gross debt | B29: 84515 | C29: 88624 | D29: 96276 | E29: 92568 | F29: 91315 | G29: 108075 | H29: 134605 | I29: 129541
A30: BS_010 — Cash and cash equivalents | B30: 10616 | C30: 10941 | D30: 17406 | E30: 10786 | F30: 10445 | G30: 19241 | H30: 38455 | I30: 31289
A31: DEBT_050 — Operating lease liabilities, current | E31: 1914 | F31: 2196 | G31: 2368 | H31: 2798 | I31: 3542
A32: DEBT_060 — Operating lease liabilities, noncurrent | E32: 11536 | F32: 14094 | G32: 16311 | H32: 18512 | I32: 26648
A33: SHARE_020 — Diluted weighted-average shares (mm) | B33: 2851 | C33: 2869 | D33: 2874 | E33: 2871 | F33: 2909 | G33: 2922 | H33: 2912 | I33: 2915

Sheet Scenario Assumptions
A1: Scenario Assumptions — D-020 (Gate 8, ratified 2026-07-21)
A2: Ranges reproduced verbatim from decision_log.md D-020. 'Selected' pulls the MIDPOINT of the scenario chosen on the Control Panel tab.
A4: Driver | B4: FY | C4: Bear low | D4: Bear high | E4: Base low | F4: Base high | G4: Bull low | H4: Bull high | I4: Selected (mid) | J4: Wired into Gate 10 forecast?
A5: OCI growth % | B5: FY27 | C5: 0.88 | D5: 0.98 | E5: 1.12 | F5: 1.18 | G5: 1.3 | H5: 1.4 | I5: =IF('Control Panel'!$B$5="Bear",AVERAGE(C5:D5),IF('Control Panel'!$B$5="Base",AVERAGE(E5:F5),AVERAGE(G5:H5))) | J5: Yes — Revenue Forecast tab
A6: OCI growth % | B6: FY28 | C6: 0.5 | D6: 0.65 | E6: 0.85 | F6: 1 | G6: 0.95 | H6: 1.15 | I6: =IF('Control Panel'!$B$5="Bear",AVERAGE(C6:D6),IF('Control Panel'!$B$5="Base",AVERAGE(E6:F6),AVERAGE(G6:H6))) | J6: Yes — Revenue Forecast tab
A7: Applications growth % | B7: FY27 | C7: 0.07 | D7: 0.09 | E7: 0.1 | F7: 0.12 | G7: 0.14 | H7: 0.16 | I7: =IF('Control Panel'!$B$5="Bear",AVERAGE(C7:D7),IF('Control Panel'!$B$5="Base",AVERAGE(E7:F7),AVERAGE(G7:H7))) | J7: Yes — Revenue Forecast tab
A8: Applications growth % | B8: FY28 | C8: 0.06 | D8: 0.08 | E8: 0.1 | F8: 0.12 | G8: 0.13 | H8: 0.15 | I8: =IF('Control Panel'!$B$5="Bear",AVERAGE(C8:D8),IF('Control Panel'!$B$5="Base",AVERAGE(E8:F8),AVERAGE(G8:H8))) | J8: Yes — Revenue Forecast tab
A9: Total revenue ($B, cross-check only) | B9: FY27 | C9: 84 | D9: 86 | E9: 89.5 | F9: 90.5 | G9: 94 | H9: 97 | I9: =IF('Control Panel'!$B$5="Bear",AVERAGE(C9:D9),IF('Control Panel'!$B$5="Base",AVERAGE(E9:F9),AVERAGE(G9:H9))) | J9: No — memo/cross-check only
A10: Total revenue ($B, cross-check only) | B10: FY28 | C10: 108 | D10: 116 | E10: 127 | F10: 132 | G10: 140 | H10: 150 | I10: =IF('Control Panel'!$B$5="Bear",AVERAGE(C10:D10),IF('Control Panel'!$B$5="Base",AVERAGE(E10:F10),AVERAGE(G10:H10))) | J10: No — memo/cross-check only
A11: GAAP gross margin % | B11: FY27 | C11: 0.53 | D11: 0.56 | E11: 0.55 | F11: 0.58 | G11: 0.58 | H11: 0.6 | I11: =IF('Control Panel'!$B$5="Bear",AVERAGE(C11:D11),IF('Control Panel'!$B$5="Base",AVERAGE(E11:F11),AVERAGE(G11:H11))) | J11: Yes — Margin & EBITDA tab
A12: GAAP gross margin % | B12: FY28 | C12: 0.5 | D12: 0.54 | E12: 0.52 | F12: 0.57 | G12: 0.57 | H12: 0.61 | I12: =IF('Control Panel'!$B$5="Bear",AVERAGE(C12:D12),IF('Control Panel'!$B$5="Base",AVERAGE(E12:F12),AVERAGE(G12:H12))) | J12: Yes — Margin & EBITDA tab
A13: Non-GAAP operating margin % | B13: FY27 | C13: 0.36 | D13: 0.385 | E13: 0.395 | F13: 0.415 | G13: 0.42 | H13: 0.44 | I13: =IF('Control Panel'!$B$5="Bear",AVERAGE(C13:D13),IF('Control Panel'!$B$5="Base",AVERAGE(E13:F13),AVERAGE(G13:H13))) | J13: Yes — Margin & EBITDA tab
A14: Non-GAAP operating margin % | B14: FY28 | C14: 0.34 | D14: 0.38 | E14: 0.385 | F14: 0.415 | G14: 0.42 | H14: 0.45 | I14: =IF('Control Panel'!$B$5="Bear",AVERAGE(C14:D14),IF('Control Panel'!$B$5="Base",AVERAGE(E14:F14),AVERAGE(G14:H14))) | J14: Yes — Margin & EBITDA tab
A15: Gross reported capex ($B) | B15: FY27 | C15: 92 | D15: 100 | E15: 90 | F15: 95 | G15: 95 | H15: 105 | I15: =IF('Control Panel'!$B$5="Bear",AVERAGE(C15:D15),IF('Control Panel'!$B$5="Base",AVERAGE(E15:F15),AVERAGE(G15:H15))) | J15: No — Gate 12 (debt/capex build)
A16: Gross capex ($B) | B16: FY28 | C16: 85 | D16: 105 | E16: 100 | F16: 115 | G16: 115 | H16: 135 | I16: =IF('Control Panel'!$B$5="Bear",AVERAGE(C16:D16),IF('Control Panel'!$B$5="Base",AVERAGE(E16:F16),AVERAGE(G16:H16))) | J16: No — Gate 12
... A27: Diluted shares (B) | B27: FY28 | C27: 3.18 | D27: 3.28 | E27: 3.11 | F27: 3.2 | G27: 3.04 | H27: 3.13 | I27: =IF('Control Panel'!$B$5="Bear",AVERAGE(C27:D27),IF('Control Panel'!$B$5="Base",AVERAGE(E27:F27),AVERAGE(G27:H27))) | J27: No — Gate 12

Sheet Revenue Forecast
A1: Revenue Forecast — FY2027 Q1 through FY2028 Q4
A2: Scenario-switched: OCI and Applications growth pull the 'Selected' scenario value from the Scenario Assumptions tab (Control Panel drives which scenario). Support/License/Hardware/Services are NOT part of D-020's ratified ranges - held at their own trailing FY26 actual growth rate (same rate FY27 and FY28) per Gate 7 Sec 3's disposition; Gate 12 should refine these once a ratified range exists. Quarterly seasonality uses FY26 empirical quarter-shares for every stream, including OCI - this is a simplification pending D-019's capacity index (Gate 12); OCI's seasonality should eventually be capacity-timing-driven, not historical-share-driven (architecture Sec 13).
A4: Field (USD $mm) | B4: FY27_Q1 | C4: FY27_Q2 | D4: FY27_Q3 | E4: FY27_Q4 | F4: FY28_Q1 | G4: FY28_Q2 | H4: FY28_Q3 | I4: FY28_Q4 | K4: FY2027 | L4: FY2028
A6: Growth rate inputs (FY27 / FY28), for traceability
A7: OCI revenue — FY27 growth rate | B7: ='Scenario Assumptions'!I5
A8: OCI revenue — FY28 growth rate | B8: ='Scenario Assumptions'!I6
A9: Cloud applications revenue — FY27 growth rate | B9: ='Scenario Assumptions'!I7
A10: Cloud applications revenue — FY28 growth rate | B10: ='Scenario Assumptions'!I8
A11: Software support revenue — FY27 growth rate | B11: 0.014445
A12: Software support revenue — FY28 growth rate | B12: 0.014445
A13: Software license revenue — FY27 growth rate | B13: -0.089406
A14: Software license revenue — FY28 growth rate | B14: -0.089406
A15: Hardware revenue — FY27 growth rate | B15: 0.050409
A16: Hardware revenue — FY28 growth rate | B16: 0.050409
A17: Services revenue — FY27 growth rate | B17: 0.097668
A18: Services revenue — FY28 growth rate | B18: 0.097668
A20: Quarterly seasonality shares (FY26 actual, held flat for FY27 & FY28)
A21: OCI revenue — quarter share of FY | B21: 0.185 | C21: 0.225 | D21: 0.27 | E21: 0.32 | F21: 0.185 | G21: 0.225 | H21: 0.27 | I21: 0.32
A22: Cloud applications revenue — quarter share of FY | B22: 0.242 | C22: 0.245 | D22: 0.253 | E22: 0.26 | F22: 0.242 | G22: 0.245 | H22: 0.253 | I22: 0.26
A23: Software support revenue — quarter share of FY | B23: 0.25 | C23: 0.249 | D23: 0.251 | E23: 0.25 | F23: 0.25 | G23: 0.249 | H23: 0.251 | I23: 0.25
A24: Software license revenue — quarter share of FY | B24: 0.162 | C24: 0.198 | D24: 0.243 | E24: 0.397 | F24: 0.162 | G24: 0.198 | H24: 0.243 | I24: 0.397
A25: Hardware revenue — quarter share of FY | B25: 0.217 | C25: 0.252 | D25: 0.232 | E25: 0.3 | F25: 0.217 | G25: 0.252 | H25: 0.232 | I25: 0.3
A26: Services revenue — quarter share of FY | B26: 0.235 | C26: 0.249 | D26: 0.251 | E26: 0.265 | F26: 0.235 | G26: 0.249 | H26: 0.251 | I26: 0.265
A28: Forecast revenue by stream
A29: OCI revenue | B29: =$K$29*B21 | C29: =$K$29*C21 | D29: =$K$29*D21 | E29: =$K$29*E21 | F29: =$L$29*F21 | G29: =$L$29*G21 | H29: =$L$29*H21 | I29: =$L$29*I21 | K29: ='Historical Actuals'!$L$5*(1+B7) | L29: =K29*(1+B8)
A30: Cloud applications revenue | B30: =$K$30*B22 | C30: =$K$30*C22 | D30: =$K$30*D22 | E30: =$K$30*E22 | F30: =$L$30*F22 | G30: =$L$30*G22 | H30: =$L$30*H22 | I30: =$L$30*I22 | K30: ='Historical Actuals'!$L$6*(1+B9) | L30: =K30*(1+B10)
A31: Software support revenue | B31: =$K$31*B23 | C31: =$K$31*C23 | D31: =$K$31*D23 | E31: =$K$31*E23 | F31: =$L$31*F23 | G31: =$L$31*G23 | H31: =$L$31*H23 | I31: =$L$31*I23 | K31: ='Historical Actuals'!$L$7*(1+B11) | L31: =K31*(1+B12)
A32: Software license revenue | B32: =$K$32*B24 | C32: =$K$32*C24 | D32: =$K$32*D24 | E32: =$K$32*E24 | F32: =$L$32*F24 | G32: =$L$32*G24 | H32: =$L$32*H24 | I32: =$L$32*I24 | K32: ='Historical Actuals'!$L$8*(1+B13) | L32: =K32*(1+B14)
A33: Hardware revenue | B33: =$K$33*B25 | C33: =$K$33*C25 | D33: =$K$33*D25 | E33: =$K$33*E25 | F33: =$L$33*F25 | G33: =$L$33*G25 | H33: =$L$33*H25 | I33: =$L$33*I25 | K33: ='Historical Actuals'!$L$9*(1+B15) | L33: =K33*(1+B16)
A34: Services revenue | B34: =$K$34*B26 | C34: =$K$34*C26 | D34: =$K$34*D26 | E34: =$K$34*E26 | F34: =$L$34*F26 | G34: =$L$34*G26 | H34: =$L$34*H26 | I34: =$L$34*I26 | K34: ='Historical Actuals'!$L$10*(1+B17) | L34: =K34*(1+B18)
A35: Total revenue (sum of six streams) | B35: =SUM(B29:B34) | C35: =SUM(C29:C34) | D35: =SUM(D29:D34) | E35: =SUM(E29:E34) | F35: =SUM(F29:F34) | G35: =SUM(G29:G34) | H35: =SUM(H29:H34) | I35: =SUM(I29:I34) | K35: =SUM(K29:K34) | L35: =SUM(L29:L34)
A37: Cross-check: Framework total-revenue Selected midpoint ($B) | K37: ='Scenario Assumptions'!I9*1000 | L37: ='Scenario Assumptions'!I10*1000
A38: Bottom-up build vs. Framework cross-check, variance ($mm) | K38: =K35-K37 | L38: =L35-L37

Sheet Capex & Depreciation
A1: Capex & Depreciation — FY2027 Q1 through FY2028 Q4
A2: Gross/net cash capex and total PP&E depreciation pull the D-020 scenario-selected midpoints. Amortization of intangibles has no ratified scenario range - held at the trailing FY26 actual level (flat), per the same treatment Gate 10 gave unratified lines. Quarterly spread for depreciation reuses the empirical FY26 quarter-shares (depreciation accelerated through FY26 as the buildout ramped - a real, not fabricated, shape); amortization is spread evenly (FY26's own quarters were nearly flat, ~25% each).
A4: Field ($mm unless noted) | B4: FY27_Q1 | C4: FY27_Q2 | D4: FY27_Q3 | E4: FY27_Q4 | F4: FY28_Q1 | G4: FY28_Q2 | H4: FY28_Q3 | I4: FY28_Q4 | K4: FY2027 | L4: FY2028
A5: Gross reported capex, annual | K5: ='Scenario Assumptions'!I15*1000 | L5: ='Scenario Assumptions'!I16*1000
A6: Net cash capex, annual (FY27 ratified only; FY28 uses gross capex as a proxy - no ratified FY28 net-cash figure) | K6: ='Scenario Assumptions'!I17*1000 | L6: =L5
A8: Depreciation (PP&E), annual — scenario-selected (D-020) | K8: ='Scenario Assumptions'!I18*1000 | L8: ='Scenario Assumptions'!I19*1000
A9: Depreciation — quarterly seasonality share (FY26 actual, held flat) | B9: 0.177227 | C9: 0.223534 | D9: 0.282435 | E9: 0.316804 | F9: 0.177227 | G9: 0.223534 | H9: 0.282435 | I9: 0.316804
A10: Depreciation (PP&E), quarterly | B10: =$K$8*B9 | C10: =$K$8*C9 | D10: =$K$8*D9 | E10: =$K$8*E9 | F10: =$L$8*F9 | G10: =$L$8*G9 | H10: =$L$8*H9 | I10: =$L$8*I9
A12: Amortization of intangibles, annual (trailing FY26 actual, held flat — no ratified range) | K12: 1671 | L12: 1671
A13: Amortization, quarterly (even spread — FY26 actual was ~25% each quarter) | B13: =$K$12/4 | C13: =$K$12/4 | D13: =$K$12/4 | E13: =$K$12/4 | F13: =$L$12/4 | G13: =$L$12/4 | H13: =$L$12/4 | I13: =$L$12/4
A15: Total D&A (Depreciation + Amortization) — feeds Margin & EBITDA per D-014 | B15: =B10+B13 | C15: =C10+C13 | D15: =D10+D13 | E15: =E10+E13 | F15: =F10+F13 | G15: =G10+G13 | H15: =H10+H13 | I15: =I10+I13 | K15: =K8+K12 | L15: =L8+L12

Sheet Debt, Leases & Cash
A1: Debt, Leases & Cash — FY2027 Q1 through FY2028 Q4
A2: Beginning balances anchor to the FY26 Q4 actuals (Gate 6 dataset). Ending gross debt and ending cash pull the D-020 scenario-selected midpoints; quarterly paths are linear interpolations between known endpoints, not a modeled issuance/repayment schedule (no such schedule is disclosed — Gate 7 Sec2 item 22 disposition). Net new debt/financing is shown as an implied plug (Ending − Beginning), not a security-by-security build. Interest expense pulls the scenario-selected annual midpoint, spread evenly by quarter (no disclosed seasonality for interest). Lease commencement schedule spreads the disclosed $260B uncommenced-lease pool (C-06) evenly across the FY2027-FY2029 commencement window stated in the FY26 10-K — a simplification given no finer schedule exists (Gate 7 Sec2 item 16 disposition).
A4: Field ($mm) | B4: FY27_Q1 | C4: FY27_Q2 | D4: FY27_Q3 | E4: FY27_Q4 | F4: FY28_Q1 | G4: FY28_Q2 | H4: FY28_Q3 | I4: FY28_Q4 | K4: FY2027 | L4: FY2028
A5: Beginning gross debt (FY26 Q4 actual) | B5: ='Historical Actuals'!I29
A6: Ending gross debt, annual — scenario-selected (D-020) | K6: ='Scenario Assumptions'!I22*1000 | L6: ='Scenario Assumptions'!I23*1000
A7: Quarterly gross debt (linear interpolation, beginning to ending) | B7: =$B$5+($K$6-$B$5)*1/4 | C7: =$B$5+($K$6-$B$5)*2/4 | D7: =$B$5+($K$6-$B$5)*3/4 | E7: =$B$5+($K$6-$B$5)*4/4 | F7: =$K$6+($L$6-$K$6)*1/4 | G7: =$K$6+($L$6-$K$6)*2/4 | H7: =$K$6+($L$6-$K$6)*3/4 | I7: =$K$6+($L$6-$K$6)*4/4 | K7: =E7 | L7: =I7
A8: Implied net debt issuance/(repayment), annual (plug = Ending − Beginning) | K8: =K6-$B$5 | L8: =L6-K6
A10: Interest expense, annual — scenario-selected (D-020) | K10: ='Scenario Assumptions'!I20*1000 | L10: ='Scenario Assumptions'!I21*1000
A11: Interest expense, quarterly (even spread) | B11: =$K$10/4 | C11: =$K$10/4 | D11: =$K$10/4 | E11: =$K$10/4 | F11: =$L$10/4 | G11: =$L$10/4 | H11: =$L$10/4 | I11: =$L$10/4
A13: On-balance-sheet lease liabilities, beginning (FY26 Q4 actual: current+noncurrent) | B13: ='Historical Actuals'!I31+'Historical Actuals'!I32
A14: Uncommenced lease pool (C-06, FY26 10-K: $260B, commencing FY2027-FY2029) | B14: 260000
A15: Lease commencement per fiscal year (pool / 3 years — simplification, no finer schedule disclosed) | K15: =$B$14/3 | L15: =$B$14/3
A16: On-balance-sheet lease liabilities, ending (cumulative: beginning + commenced-to-date) | K16: =$B$13+K15 | L16: =K16+L15
A18: Beginning cash (FY26 Q4 actual) | B18: ='Historical Actuals'!I30
A19: Ending cash, annual — scenario-selected (D-020) | K19: ='Scenario Assumptions'!I24*1000 | L19: ='Scenario Assumptions'!I25*1000
A20: Quarterly cash (linear interpolation, beginning to ending) | B20: =$B$18+($K$19-$B$18)*1/4 | C20: =$B$18+($K$19-$B$18)*2/4 | D20: =$B$18+($K$19-$B$18)*3/4 | E20: =$B$18+($K$19-$B$18)*4/4 | F20: =$K$19+($L$19-$K$19)*1/4 | G20: =$K$19+($L$19-$K$19)*2/4 | H20: =$K$19+($L$19-$K$19)*3/4 | I20: =$K$19+($L$19-$K$19)*4/4 | K20: =E20 | L20: =I20
A22: Quarterly on-balance-sheet lease liabilities (linear interpolation, beginning to ending) | B22: =$B$13+($K$16-$B$13)*1/4 | C22: =$B$13+($K$16-$B$13)*2/4 | D22: =$B$13+($K$16-$B$13)*3/4 | E22: =$B$13+($K$16-$B$13)*4/4 | F22: =$K$16+($L$16-$K$16)*1/4 | G22: =$K$16+($L$16-$K$16)*2/4 | H22: =$K$16+($L$16-$K$16)*3/4 | I22: =$K$16+($L$16-$K$16)*4/4 | K22: =E22 | L22: =I22
A24: Marketable securities (held flat at FY26 Q4 actual — no forecast built, immaterial: $605mm) | B24: 605
A25: Preferred/mandatory convertible carrying value (held flat at FY26 Q4 actual — Q-11 treatment unresolved) | B25: 4954

Sheet Equity & Shares
A1: Equity & Diluted Shares — FY2027 Q1 through FY2028 Q4
A2: Diluted shares pull the D-020 scenario-selected midpoint directly (in billions, per the ratified table) rather than being re-derived from an assumed ATM issuance price - Gate 7 Sec6 flags ATM price/pace as explicitly reflexive with the (not-yet-computed) valuation output, so backing into shares from a guessed price here would be circular. Quarterly path is a linear interpolation from the FY26 Q4 actual to each ratified annual endpoint.
A4: Field | B4: FY27_Q1 | C4: FY27_Q2 | D4: FY27_Q3 | E4: FY27_Q4 | F4: FY28_Q1 | G4: FY28_Q2 | H4: FY28_Q3 | I4: FY28_Q4 | K4: FY2027 | L4: FY2028
A5: Beginning diluted shares, mm (FY26 Q4 actual) | B5: ='Historical Actuals'!I33
A6: Ending diluted shares, annual, mm — scenario-selected (D-020, x1000 from B) | K6: ='Scenario Assumptions'!I26*1000 | L6: ='Scenario Assumptions'!I27*1000
A7: Quarterly diluted shares, mm (linear interpolation) | B7: =$B$5+($K$6-$B$5)*1/4 | C7: =$B$5+($K$6-$B$5)*2/4 | D7: =$B$5+($K$6-$B$5)*3/4 | E7: =$B$5+($K$6-$B$5)*4/4 | F7: =$K$6+($L$6-$K$6)*1/4 | G7: =$K$6+($L$6-$K$6)*2/4 | H7: =$K$6+($L$6-$K$6)*3/4 | I7: =$K$6+($L$6-$K$6)*4/4 | K7: =E7 | L7: =I7
A9: Implied net share change, annual (plug = Ending − Beginning, mm) | K9: =K6-$B$5 | L9: =L6-K6

Sheet Margin & EBITDA
A1: Margin & EBITDA — Forecast (top-down, per Gate 7 Sec 5)
A2: No stream-level margin is ever disclosed by Oracle (architecture Sec 8/16), so margin is forecast top-down from the scenario-switched consolidated ratios, applied to the bottom-up revenue build on the Revenue Forecast tab. EBITDA uses the ratified D-014 definition: GAAP operating income + D&A, with D&A now linked to the split Depreciation/Amortization build on the Capex & Depreciation tab (Gate 12).
A4: Field | B4: FY27_Q1 | C4: FY27_Q2 | D4: FY27_Q3 | E4: FY27_Q4 | F4: FY28_Q1 | G4: FY28_Q2 | H4: FY28_Q3 | I4: FY28_Q4 | K4: FY2027 | L4: FY2028
A5: Total revenue (='Revenue Forecast'!) | B5: ='Revenue Forecast'!B35 | C5: ='Revenue Forecast'!C35 | D5: ='Revenue Forecast'!D35 | E5: ='Revenue Forecast'!E35 | F5: ='Revenue Forecast'!F35 | G5: ='Revenue Forecast'!G35 | H5: ='Revenue Forecast'!H35 | I5: ='Revenue Forecast'!I35 | K5: ='Revenue Forecast'!K35 | L5: ='Revenue Forecast'!L35
A6: GAAP gross margin % (scenario-selected, annual) | B6: =$K$6 | C6: =$K$6 | D6: =$K$6 | E6: =$K$6 | F6: =$L$6 | G6: =$L$6 | H6: =$L$6 | I6: =$L$6 | K6: ='Scenario Assumptions'!I11 | L6: ='Scenario Assumptions'!I12
A7: Gross profit (=Revenue x GAAP gross margin) | B7: =B5*B6 | C7: =C5*C6 | D7: =D5*D6 | E7: =E5*E6 | F7: =F5*F6 | G7: =G5*G6 | H7: =H5*H6 | I7: =I5*I6 | K7: =K5*K6 | L7: =L5*L6
A8: Non-GAAP operating margin % (scenario-selected, annual) | B8: =$K$8 | C8: =$K$8 | D8: =$K$8 | E8: =$K$8 | F8: =$L$8 | G8: =$L$8 | H8: =$L$8 | I8: =$L$8 | K8: ='Scenario Assumptions'!I13 | L8: ='Scenario Assumptions'!I14
A9: Non-GAAP operating income (=Revenue x Non-GAAP op margin) | B9: =B5*B8 | C9: =C5*C8 | D9: =D5*D8 | E9: =E5*E8 | F9: =F5*F8 | G9: =G5*G8 | H9: =H5*H8 | I9: =I5*I8 | K9: =K5*K8 | L9: =L5*L8
A11: D&A (linked from Capex & Depreciation tab: Depreciation + Amortization, per D-014) | B11: ='Capex & Depreciation'!B15 | C11: ='Capex & Depreciation'!C15 | D11: ='Capex & Depreciation'!D15 | E11: ='Capex & Depreciation'!E15 | F11: ='Capex & Depreciation'!F15 | G11: ='Capex & Depreciation'!G15 | H11: ='Capex & Depreciation'!H15 | I11: ='Capex & Depreciation'!I15 | K11: ='Capex & Depreciation'!K15 | L11: ='Capex & Depreciation'!L15 | M11: Now linked to the split Depreciation/Amortization build (Gate 12) instead of a combined envelope
A12: EBITDA, annual (D-014: Non-GAAP op income proxy not used; = GAAP op income + D&A) | M12: See note below - EBITDA built from GAAP operating income (row proxy) + D&A envelope
A13: GAAP operating margin % (historical FY26 actual, held flat - no ratified scenario range exists for this line) | B13: 0.3033 | C13: 0.3033 | D13: 0.3033 | E13: 0.3033 | F13: 0.3033 | G13: 0.3033 | H13: 0.3033 | I13: 0.3033 | K13: 0.3033 | L13: 0.3033
A14: GAAP operating income (=Revenue x GAAP operating margin) | B14: =B5*B13 | C14: =C5*C13 | D14: =D5*D13 | E14: =E5*E13 | F14: =F5*F13 | G14: =G5*G13 | H14: =H5*H13 | I14: =I5*I13 | K14: =K5*K13 | L14: =L5*L13
A15: EBITDA (D-014: GAAP operating income + D&A envelope) | B15: =B14+B11 | C15: =C14+C11 | D15: =D14+D11 | E15: =E14+E11 | F15: =F14+F11 | G15: =G14+G11 | H15: =H14+H11 | I15: =I14+I11 | K15: =K14+K11 | L15: =L14+L11
A17: Note: GAAP operating margin is held at the FY26 annual actual (30.33%) rather than scenario-switched, because D-020 ratified GAAP GROSS margin and Non-GAAP OPERATING margin, not a GAAP operating margin range - there is no ratified number to switch this line to. Gate 12 should either derive GAAP operating income as Non-GAAP operating income less the historical GAAP/non-GAAP opex bridge (OPEX_040/050/060/070), or ask the user to ratify a GAAP operating margin range directly.
A20: Net Income & EPS bridge (Gate 13)
A21: Interest expense (link, Debt/Leases & Cash tab) | B21: ='Debt, Leases & Cash'!B11 | C21: ='Debt, Leases & Cash'!C11 | D21: ='Debt, Leases & Cash'!D11 | E21: ='Debt, Leases & Cash'!E11 | F21: ='Debt, Leases & Cash'!F11 | G21: ='Debt, Leases & Cash'!G11 | H21: ='Debt, Leases & Cash'!H11 | I21: ='Debt, Leases & Cash'!I11 | K21: ='Debt, Leases & Cash'!K11 | L21: ='Debt, Leases & Cash'!L11
A22: Pre-tax income (=GAAP operating income − interest expense; non-operating items excluded by construction, per D-014) | B22: =B14-B21 | C22: =C14-C21 | D22: =D14-D21 | E22: =E14-E21 | F22: =F14-F21 | G22: =G14-G21 | H22: =H14-H21 | I22: =I14-I21 | K22: =K14-K21 | L22: =L14-L21
A23: Effective tax rate (trailing FY26 actual, held flat — no ratified scenario range) | B23: 0.1262 | C23: 0.1262 | D23: 0.1262 | E23: 0.1262 | F23: 0.1262 | G23: 0.1262 | H23: 0.1262 | I23: 0.1262 | K23: 0.1262 | L23: 0.1262
A24: Income tax provision | B24: =B22*B23 | C24: =C22*C23 | D24: =D22*D23 | E24: =E22*E23 | F24: =F22*F23 | G24: =G22*G23 | H24: =H22*H23 | I24: =I22*I23 | K24: =K22*K23 | L24: =L22*L23
A25: GAAP net income (=Pre-tax income − tax provision) | B25: =B22-B24 | C25: =C22-C24 | D25: =D22-D24 | E25: =E22-E24 | F25: =F22-F24 | G25: =G22-G24 | H25: =H22-H24 | I25: =I22-I24 | K25: =K22-K24 | L25: =L22-L24
A26: Preferred dividends (held flat at FY26 Q4 actual rate, $81mm/qtr — Q-11 debt-like default) | B26: 81 | C26: 81 | D26: 81 | E26: 81 | F26: 81 | G26: 81 | H26: 81 | I26: 81 | K26: =SUM(B26:E26) | L26: =SUM(F26:I26)
A27: Net income available to common shareholders | B27: =B25-B26 | C27: =C25-C26 | D27: =D25-D26 | E27: =E25-E26 | F27: =F25-F26 | G27: =G25-G26 | H27: =H25-H26 | I27: =I25-I26 | K27: =K25-K26 | L27: =L25-L26
A28: Diluted shares, mm (link, Equity & Shares tab) | B28: ='Equity & Shares'!B7 | C28: ='Equity & Shares'!C7 | D28: ='Equity & Shares'!D7 | E28: ='Equity & Shares'!E7 | F28: ='Equity & Shares'!F7 | G28: ='Equity & Shares'!G7 | H28: ='Equity & Shares'!H7 | I28: ='Equity & Shares'!I7 | K28: ='Equity & Shares'!K7 | L28: ='Equity & Shares'!L7
A29: GAAP diluted EPS | B29: =B27/B28 | C29: =C27/C28 | D29: =D27/D28 | E29: =E27/E28 | F29: =F27/F28 | G29: =G27/G28 | H29: =H27/H28 | I29: =I27/I28 | K29: =K27/K28 | L29: =L27/L28

Sheet Cash Flow & Returns
A1: Cash Flow & Returns — includes D-021's five capital-adjusted valuation controls
A2: Operating cash flow is solved as a PLUG from the cash identity (Beginning cash + OCF − Net cash capex + Net debt issuance = Ending cash), since D-020 ratifies the endpoints (ending cash, ending debt) but not a full operating cash flow build. The plug absorbs dividends, buybacks, and any other financing/investing items not separately modeled at Gate 12 - it is a reconciling figure, not a bottom-up forecast, and is labeled as such. Rows below it (EBITDA less capex, OCF less capex, capex/revenue, lease-adjusted net leverage) are the five controls the primary EV/NTM EBITDA method is required to carry alongside it, per D-021 Sec1. Incremental ROIC (D-021's fifth control) is NOT built - it needs an invested-capital base beyond Gate 12's balance-sheet scope; flagged for Gate 13.
A4: Field ($mm) | B4: FY27_Q1 | C4: FY27_Q2 | D4: FY27_Q3 | E4: FY27_Q4 | F4: FY28_Q1 | G4: FY28_Q2 | H4: FY28_Q3 | I4: FY28_Q4 | K4: FY2027 | L4: FY2028
A5: Total revenue (link) | B5: ='Margin & EBITDA'!B5 | C5: ='Margin & EBITDA'!C5 | D5: ='Margin & EBITDA'!D5 | E5: ='Margin & EBITDA'!E5 | F5: ='Margin & EBITDA'!F5 | G5: ='Margin & EBITDA'!G5 | H5: ='Margin & EBITDA'!H5 | I5: ='Margin & EBITDA'!I5 | K5: ='Margin & EBITDA'!K5 | L5: ='Margin & EBITDA'!L5
A6: EBITDA (link, D-014 definition) | B6: ='Margin & EBITDA'!B15 | C6: ='Margin & EBITDA'!C15 | D6: ='Margin & EBITDA'!D15 | E6: ='Margin & EBITDA'!E15 | F6: ='Margin & EBITDA'!F15 | G6: ='Margin & EBITDA'!G15 | H6: ='Margin & EBITDA'!H15 | I6: ='Margin & EBITDA'!I15 | K6: ='Margin & EBITDA'!K15 | L6: ='Margin & EBITDA'!L15
A7: Net cash capex (link, Capex & Depreciation tab) | K7: ='Capex & Depreciation'!K6 | L7: ='Capex & Depreciation'!L6
A8: Gross reported capex (link, for the capex/revenue control) | K8: ='Capex & Depreciation'!K5 | L8: ='Capex & Depreciation'!L5
A10: Beginning cash (link) | K10: ='Debt, Leases & Cash'!$B$18
A11: Ending cash (link) | K11: ='Debt, Leases & Cash'!K19 | L11: ='Debt, Leases & Cash'!L19
A12: Net debt issuance/(repayment) (link) | K12: ='Debt, Leases & Cash'!K8 | L12: ='Debt, Leases & Cash'!L8
A13: Implied operating cash flow (PLUG): Ending cash − Beginning cash + Net cash capex − Net debt issuance | K13: =K11-K10+K7-K12 | L13: =L11-K11+L7-L12
A15: Free cash flow (= Implied OCF − Net cash capex) | K15: =K13-K7 | L15: =L13-L7
A17: D-021 Control 1 — Capex as % of revenue (gross capex / total revenue) | K17: =K8/K5 | L17: =L8/L5
A18: D-021 Control 2 — EBITDA less capex (net cash capex) | K18: =K6-K7 | L18: =L6-L7
A19: D-021 Control 3 — Operating cash flow less capex (= FCF above) | K19: =K15 | L19: =L15
A20: D-021 Control 4 — Lease-adjusted net debt (gross debt + on-BS lease liabilities − cash) | K20: ='Debt, Leases & Cash'!K6+'Debt, Leases & Cash'!K16-'Debt, Leases & Cash'!K19 | L20: ='Debt, Leases & Cash'!L6+'Debt, Leases & Cash'!L16-'Debt, Leases & Cash'!L19
A21: D-021 Control 4 — Lease-adjusted net leverage (lease-adj. net debt / EBITDA) | K21: =K20/K6 | L21: =L20/L6
A23: D-021 Control 5 — Incremental ROIC — NOT built at Gate 12 (needs invested-capital base; Gate 13)

Sheet Valuation (Gate 13)
A1: Valuation — NTM Aggregation & Enterprise-to-Equity Bridge
A2: Built per Framework Sec14/15 and D-021's methodology. NTM windows are exactly the four the Framework specifies (Q-07), summed directly from the forecast tabs. The enterprise-to-equity bridge components (debt, leases, preferred, cash) are pulled at the balance as of the quarter just completed at each valuation date. THE MULTIPLE CELLS BELOW ARE BLANK BY DESIGN: assigning a real EV/NTM EBITDA or P/NTM EPS multiple needs live, as-of-dated peer market data, which this session does not have (Q-08: FactSet connector unauthenticated; C-09: existing comp table is stale/single-sourced/illustrative-only per the Gate 9 methodology). Filling a real number into an LLM's general knowledge of current prices would violate this project's no-fabricated-data rule — so those cells stay blank, highlighted, for the user or an authenticated data source to fill in. An ILLUSTRATIVE-ONLY section further below demonstrates the mechanism using the Framework's own explicitly-unadopted candidate multiple ranges (never treat that section's output as a real target).
A4: Scenario in effect (link, Control Panel) | B4: ='Control Panel'!B5
A6: 1. NTM aggregation at each valuation date
A7: Valuation date | B7: Expected timing | C7: NTM revenue ($mm) | D7: NTM EBITDA ($mm) | E7: NTM EPS ($)
A8: FY27 Q1 release | B8: 2026-09-10 (management-scheduled) | C8: ='Revenue Forecast'!C35+'Revenue Forecast'!D35+'Revenue Forecast'!E35+'Revenue Forecast'!F35 | D8: ='Margin & EBITDA'!C15+'Margin & EBITDA'!D15+'Margin & EBITDA'!E15+'Margin & EBITDA'!F15 | E8: ='Margin & EBITDA'!C29+'Margin & EBITDA'!D29+'Margin & EBITDA'!E29+'Margin & EBITDA'!F29
A9: FY27 Q2 release | B9: est. December 2026 | C9: ='Revenue Forecast'!D35+'Revenue Forecast'!E35+'Revenue Forecast'!F35+'Revenue Forecast'!G35 | D9: ='Margin & EBITDA'!D15+'Margin & EBITDA'!E15+'Margin & EBITDA'!F15+'Margin & EBITDA'!G15 | E9: ='Margin & EBITDA'!D29+'Margin & EBITDA'!E29+'Margin & EBITDA'!F29+'Margin & EBITDA'!G29
A10: FY27 Q3 release | B10: est. March 2027 | C10: ='Revenue Forecast'!E35+'Revenue Forecast'!F35+'Revenue Forecast'!G35+'Revenue Forecast'!H35 | D10: ='Margin & EBITDA'!E15+'Margin & EBITDA'!F15+'Margin & EBITDA'!G15+'Margin & EBITDA'!H15 | E10: ='Margin & EBITDA'!E29+'Margin & EBITDA'!F29+'Margin & EBITDA'!G29+'Margin & EBITDA'!H29
A11: FY27 Q4 release | B11: est. June 2027 | C11: ='Revenue Forecast'!F35+'Revenue Forecast'!G35+'Revenue Forecast'!H35+'Revenue Forecast'!I35 | D11: ='Margin & EBITDA'!F15+'Margin & EBITDA'!G15+'Margin & EBITDA'!H15+'Margin & EBITDA'!I15 | E11: ='Margin & EBITDA'!F29+'Margin & EBITDA'!G29+'Margin & EBITDA'!H29+'Margin & EBITDA'!I29
A14: 2. Enterprise-to-equity bridge components at each valuation date (balance as of the just-completed quarter)
A15: Valuation date | B15: Gross debt | C15: Lease liab. (on-BS) | D15: Preferred | E15: Cash + mkt. sec.
A16: FY27 Q1 release | B16: ='Debt, Leases & Cash'!B7 | C16: ='Debt, Leases & Cash'!B22 | D16: ='Debt, Leases & Cash'!$B$25 | E16: ='Debt, Leases & Cash'!B20+'Debt, Leases & Cash'!$B$24
A17: FY27 Q2 release | B17: ='Debt, Leases & Cash'!C7 | C17: ='Debt, Leases & Cash'!C22 | D17: ='Debt, Leases & Cash'!$B$25 | E17: ='Debt, Leases & Cash'!C20+'Debt, Leases & Cash'!$B$24
A18: FY27 Q3 release | B18: ='Debt, Leases & Cash'!D7 | C18: ='Debt, Leases & Cash'!D22 | D18: ='Debt, Leases & Cash'!$B$25 | E18: ='Debt, Leases & Cash'!D20+'Debt, Leases & Cash'!$B$24
A19: FY27 Q4 release | B19: ='Debt, Leases & Cash'!E7 | C19: ='Debt, Leases & Cash'!E22 | D19: ='Debt, Leases & Cash'!$B$25 | E19: ='Debt, Leases & Cash'!E20+'Debt, Leases & Cash'!$B$24
A20: Preferred treatment: debt-like (subtracted; preferred dividends stay in the income statement, not converted to common shares). Q-11 substantively resolved 2026-07-22 (D-028): Oracle's Series D preferred mandatorily converts ~2029-01-15 - after all four of this project's valuation dates - so debt-like treatment is structurally correct here, not a placeholder default. Lease liabilities included in EV bridge (Q-13 still unresolved - verify peer multiples use the same convention before relying on this bridge for a real number).
A22: 3. Multiple assignment — BLOCKED (Q-08/C-09)
A23: Valuation date | B23: EV/NTM EBITDA (bear/base/bull) | C23: P/NTM EPS (bear/base/bull)
A24: FY27 Q1 release
A25: FY27 Q2 release
A26: FY27 Q3 release
A27: FY27 Q4 release
A28: Fill in once Q-08 is resolved (FactSet authenticated, or user-supplied as-of-dated peer data) — do not fill from general knowledge.
A30: 3b. Market-implied cross-check multiple (rank-6, single-entity — not a peer comp)
A31: Oracle's OWN current EV divided by its OWN current NTM EBITDA consensus, as computed by one research tool (Gemini, 2026-07-22, citing Barchart EV and a Street NTM EBITDA figure). This is a single-entity ratio, not exposed to the peer-to-peer methodology mismatch that makes the peer comp multiples (C-12) unusable right now - the two research tools' peer multiples for MSFT/AMZN/GOOGL/SAP/CRM/IBM disagree by 25-60% and are NOT used here. Still rank 6 (research-tool output, not independently fetched from a named terminal) - a real signal, not a sourced peer multiple, and does not resolve Q-08/C-09.
A32: Metric | B32: Value | C32: Source | D32: As-of date
A33: ORCL current enterprise value | B33: $445.6B (Gemini) / $468.6B (ChatGPT) - see C-12-adjacent note below | C33: Gemini: Barchart. ChatGPT: self-calc from market cap+debt+preferred-cash | D33: 2026-07-22
A34: ORCL current NTM EBITDA consensus (Gemini) | B34: $32.4B | C34: Gemini report, provider not fully specified per-row | D34: 2026-07-22
A35: ORCL current market-implied EV/NTM EBITDA | B35: 13.76x | C35: Gemini report (self-calculated EV / NTM EBITDA) | D35: 2026-07-22
A36: Note: this 13.76x market-implied multiple sits almost exactly on the illustrative Base case's 13.0x used since Gate 9 (Framework Sec8's unadopted candidate) - a useful real-world sanity check that the illustrative Base assumption was not unreasonable, but it is today's multiple for today's NTM window, not necessarily the multiple the market will apply at any of the four future valuation dates below.
A40: 4. ILLUSTRATIVE ONLY — mechanism demo using the Framework's unadopted candidate multiples (NOT a real valuation)
A41: Valuation date | B41: Illustrative EV (Base, $mm) | C41: Illustrative equity value (Base, $mm) | D41: Illustrative implied price (Base, $/sh)
A42: FY27 Q1 release | B42: =D8*13.0 | C42: =B32-B16-C16-D16+E16 | D42: =C32/'Equity & Shares'!B7
A43: FY27 Q2 release | B43: =D9*13.0 | C43: =B33-B17-C17-D17+E17 | D43: =C33/'Equity & Shares'!C7
A44: FY27 Q3 release | B44: =D10*13.0 | C44: =B34-B18-C18-D18+E18 | D44: =C34/'Equity & Shares'!D7
A45: FY27 Q4 release | B45: =D11*13.0 | C45: =B35-B19-C19-D19+E19 | D45: =C35/'Equity & Shares'!E7
A46: Illustrative only: uses Framework Sec8's unadopted 12x-14x base EV/NTM EBITDA range (midpoint 13.0x), never sourced from live peer data. Do not quote as a price target.

Sheet Sensitivities (Gate 14)
A1: Sensitivities — Illustrative Bear/Base/Bull Price Range (FY27 Q1 Valuation Date)
A2: ILLUSTRATIVE ONLY, same basis as the Valuation tab: uses the Framework's own unadopted candidate multiple ranges (Sec8), never a sourced multiple (Q-08/C-09 still block that). Bear/Bull NTM revenue and D&A are computed here directly from the Scenario Assumptions Bear/Bull columns (not routed through the single Control-Panel switch, which only drives one case at a time) — same seasonality shares and same held-flat GAAP operating margin/tax rate/amortization as the Base case (those lines have no ratified scenario range, so they don't differ across Bear/Base/Bull here — a simplification carried over from Gate 12/13, not a new one). Debt/cash/shares bridge components use each scenario's own D-020 ending range, interpolated to the same quarter as the Base case's bridge on the Valuation tab.
A4: 1. NTM revenue by stream (FY27 Q2 - FY28 Q1 window), Bear vs. Bull
A5: Stream | B5: Bear ($mm) | C5: Bull ($mm)
A6: OCI | B6: =('Historical Actuals'!$L$5*(1+AVERAGE('Scenario Assumptions'!C5:D5)))*(SUM('Revenue Forecast'!C21:E21))+(('Historical Actuals'!$L$5*(1+AVERAGE('Scenario Assumptions'!C5:D5)))*(1+AVERAGE('Scenario Assumptions'!C6:D6)))*'Revenue Forecast'!F21 | C6: =('Historical Actuals'!$L$5*(1+AVERAGE('Scenario Assumptions'!G5:H5)))*(SUM('Revenue Forecast'!C21:E21))+(('Historical Actuals'!$L$5*(1+AVERAGE('Scenario Assumptions'!G5:H5)))*(1+AVERAGE('Scenario Assumptions'!G6:H6)))*'Revenue Forecast'!F21
A7: Cloud applications | B7: =('Historical Actuals'!$L$6*(1+AVERAGE('Scenario Assumptions'!C7:D7)))*(SUM('Revenue Forecast'!C22:E22))+(('Historical Actuals'!$L$6*(1+AVERAGE('Scenario Assumptions'!C7:D7)))*(1+AVERAGE('Scenario Assumptions'!C8:D8)))*'Revenue Forecast'!F22 | C7: =('Historical Actuals'!$L$6*(1+AVERAGE('Scenario Assumptions'!G7:H7)))*(SUM('Revenue Forecast'!C22:E22))+(('Historical Actuals'!$L$6*(1+AVERAGE('Scenario Assumptions'!G7:H7)))*(1+AVERAGE('Scenario Assumptions'!G8:H8)))*'Revenue Forecast'!F22
A8: Software support | B8: =('Historical Actuals'!$L$7*(1+'Revenue Forecast'!$B$11))*(SUM('Revenue Forecast'!C23:E23))+(('Historical Actuals'!$L$7*(1+'Revenue Forecast'!$B$11))*(1+'Revenue Forecast'!$B$12))*'Revenue Forecast'!F23 | C8: =('Historical Actuals'!$L$7*(1+'Revenue Forecast'!$B$11))*(SUM('Revenue Forecast'!C23:E23))+(('Historical Actuals'!$L$7*(1+'Revenue Forecast'!$B$11))*(1+'Revenue Forecast'!$B$12))*'Revenue Forecast'!F23
A9: Software license | B9: =('Historical Actuals'!$L$8*(1+'Revenue Forecast'!$B$13))*(SUM('Revenue Forecast'!C24:E24))+(('Historical Actuals'!$L$8*(1+'Revenue Forecast'!$B$13))*(1+'Revenue Forecast'!$B$14))*'Revenue Forecast'!F24 | C9: =('Historical Actuals'!$L$8*(1+'Revenue Forecast'!$B$13))*(SUM('Revenue Forecast'!C24:E24))+(('Historical Actuals'!$L$8*(1+'Revenue Forecast'!$B$13))*(1+'Revenue Forecast'!$B$14))*'Revenue Forecast'!F24
A10: Hardware | B10: =('Historical Actuals'!$L$9*(1+'Revenue Forecast'!$B$15))*(SUM('Revenue Forecast'!C25:E25))+(('Historical Actuals'!$L$9*(1+'Revenue Forecast'!$B$15))*(1+'Revenue Forecast'!$B$16))*'Revenue Forecast'!F25 | C10: =('Historical Actuals'!$L$9*(1+'Revenue Forecast'!$B$15))*(SUM('Revenue Forecast'!C25:E25))+(('Historical Actuals'!$L$9*(1+'Revenue Forecast'!$B$15))*(1+'Revenue Forecast'!$B$16))*'Revenue Forecast'!F25
A11: Services | B11: =('Historical Actuals'!$L$10*(1+'Revenue Forecast'!$B$17))*(SUM('Revenue Forecast'!C26:E26))+(('Historical Actuals'!$L$10*(1+'Revenue Forecast'!$B$17))*(1+'Revenue Forecast'!$B$18))*'Revenue Forecast'!F26 | C11: =('Historical Actuals'!$L$10*(1+'Revenue Forecast'!$B$17))*(SUM('Revenue Forecast'!C26:E26))+(('Historical Actuals'!$L$10*(1+'Revenue Forecast'!$B$17))*(1+'Revenue Forecast'!$B$18))*'Revenue Forecast'!F26
A12: Total NTM revenue | B12: =SUM(B6:B11) | C12: =SUM(C6:C11) | D12: ='Valuation (Gate 13)'!C8
A14: 2. NTM D&A and EBITDA, Bear vs. Bull (Base linked from Valuation tab)
A15: Field | B15: Bear ($mm) | C15: Bull ($mm) | D15: Base (link)
A16: NTM depreciation (PP&E) | B16: =AVERAGE('Scenario Assumptions'!C18:D18)*1000*(SUM('Capex & Depreciation'!C9:E9))+AVERAGE('Scenario Assumptions'!C19:D19)*1000*'Capex & Depreciation'!F9 | C16: =AVERAGE('Scenario Assumptions'!G18:H18)*1000*(SUM('Capex & Depreciation'!C9:E9))+AVERAGE('Scenario Assumptions'!G19:H19)*1000*'Capex & Depreciation'!F9
A17: NTM amortization of intangibles (flat, not scenario-differentiated — no ratified range) | B17: =SUM('Capex & Depreciation'!C13:F13) | C17: =SUM('Capex & Depreciation'!C13:F13)
A18: NTM D&A total | B18: =B16+B17 | C18: =C16+C17
A19: NTM GAAP operating income (=NTM revenue x flat GAAP op. margin 30.33% — same limitation as Base, no ratified range differentiates this by scenario) | B19: =B12*0.3033 | C19: =C12*0.3033
A20: NTM EBITDA (=GAAP operating income + D&A, per D-014) | B20: =B19+B18 | C20: =C19+C18 | D20: ='Valuation (Gate 13)'!D8
A22: 3. Bridge components at FY27 Q1 (end): Bear / Base / Bull
A23: Field | B23: Bear ($mm) | C23: Base ($mm, link) | D23: Bull ($mm)
A24: Gross debt (interpolated, beginning to scenario's own FY27-end) | B24: ='Debt, Leases & Cash'!$B$5+(AVERAGE('Scenario Assumptions'!C22:D22)*1000-'Debt, Leases & Cash'!$B$5)*1/4 | C24: ='Debt, Leases & Cash'!B7 | D24: ='Debt, Leases & Cash'!$B$5+(AVERAGE('Scenario Assumptions'!G22:H22)*1000-'Debt, Leases & Cash'!$B$5)*1/4
A25: On-balance lease liabilities (not scenario-differentiated — fixed disclosed commencement schedule, C-06) | B25: ='Debt, Leases & Cash'!B22 | C25: ='Debt, Leases & Cash'!B22 | D25: ='Debt, Leases & Cash'!B22
A26: Preferred (held flat, Q-11 debt-like default — not scenario-differentiated) | B26: ='Debt, Leases & Cash'!$B$25 | C26: ='Debt, Leases & Cash'!$B$25 | D26: ='Debt, Leases & Cash'!$B$25
A27: Cash + marketable securities (interpolated, beginning to scenario's own FY27-end) | B27: ='Debt, Leases & Cash'!$B$18+(AVERAGE('Scenario Assumptions'!C24:D24)*1000-'Debt, Leases & Cash'!$B$18)*1/4+'Debt, Leases & Cash'!$B$24 | C27: ='Debt, Leases & Cash'!B20+'Debt, Leases & Cash'!$B$24 | D27: ='Debt, Leases & Cash'!$B$18+(AVERAGE('Scenario Assumptions'!G24:H24)*1000-'Debt, Leases & Cash'!$B$18)*1/4+'Debt, Leases & Cash'!$B$24
A28: Diluted shares, mm (interpolated, beginning to scenario's own FY27-end) | B28: ='Equity & Shares'!$B$5+(AVERAGE('Scenario Assumptions'!C26:D26)*1000-'Equity & Shares'!$B$5)*1/4 | C28: ='Equity & Shares'!B7 | D28: ='Equity & Shares'!$B$5+(AVERAGE('Scenario Assumptions'!G26:H26)*1000-'Equity & Shares'!$B$5)*1/4
A30: 4. ILLUSTRATIVE bear/base/bull implied price (FY27 Q1 valuation date) — NOT a real price target
B31: Bear | C31: Base | D31: Bull
A32: Illustrative EV/NTM EBITDA multiple (Framework Sec8 unadopted candidate midpoint) | B32: 10 | C32: 13 | D32: 16
A33: NTM EBITDA feeding this multiple ($mm) | B33: =B20 | C33: ='Valuation (Gate 13)'!D8 | D33: =C20
A34: Illustrative EV ($mm) | B34: =B33*B32 | C34: =C33*C32 | D34: =D33*D32
A35: Illustrative equity value ($mm) | B35: =B34-B24-B25-B26+B27 | C35: =C34-C24-C25-C26+C27 | D35: =D34-D24-D25-D26+D27
A36: Illustrative implied price ($/sh) | B36: =B35/B28 | C36: =C35/C28 | D36: =D35/D28
A38: Note: this is a closed-form, single-valuation-date (FY27 Q1) approximation, not a full quarterly Bear/Bull rebuild — it reuses the Base case's held-flat GAAP operating margin, effective tax rate, and seasonality shares for all three scenarios (those lines have no ratified scenario range regardless), and differentiates Bear/Base/Bull only through the D-020 ranges that actually vary by scenario (OCI/applications growth, depreciation, ending debt/cash/shares). Cross-check: the Base column should tie closely to the Valuation tab's own illustrative price at this same date ($165.57 under the Base 13.0x case) — small differences reflect this tab computing Bear/Bull's own bridge quarter-end via interpolation rather than a full quarterly rebuild.
A41: 5. One-way sensitivity: illustrative Base-case price vs. EV/NTM EBITDA multiple
A42: Holds Base-case NTM EBITDA and bridge components fixed; varies only the multiple. Same illustrative-only caveat as everywhere else on this tab.
A43: Multiple | B43: Implied EV ($mm) | C43: Implied equity value ($mm) | D43: Implied price ($/sh)
A44: 9 | B44: =A44*C$33 | C44: =B44-C$24-C$25-C$26+C$27 | D44: =C44/C$28
A45: 10 | B45: =A45*C$33 | C45: =B45-C$24-C$25-C$26+C$27 | D45: =C45/C$28
A46: 11 | B46: =A46*C$33 | C46: =B46-C$24-C$25-C$26+C$27 | D46: =C46/C$28
A47: 12 | B47: =A47*C$33 | C47: =B47-C$24-C$25-C$26+C$27 | D47: =C47/C$28
...

Sheet Checks
A1: Checks — Gate 10 minimal build
A2: Green = tie, zero variance. Red = investigate. Historical checks re-verify Gate 6's own reconciliation (belt-and-suspenders inside the model itself); forecast checks confirm the build mechanics hold together, not that the forecast is 'correct' (there is no ground truth for a forecast — only internal consistency).
A4: CHECK_020 — Historical: six-stream sum = Total revenue (REV_370)
A5: Period | B5: FY25_Q1 | C5: FY25_Q2 | D5: FY25_Q3 | E5: FY25_Q4 | F5: FY26_Q1 | G5: FY26_Q2 | H5: FY26_Q3 | I5: FY26_Q4
A6: Variance ($mm), should be exactly 0 | B6: ='Historical Actuals'!B11-SUM('Historical Actuals'!B5:B10) | C6: ='Historical Actuals'!C11-SUM('Historical Actuals'!C5:C10) | D6: ='Historical Actuals'!D11-SUM('Historical Actuals'!D5:D10) | E6: ='Historical Actuals'!E11-SUM('Historical Actuals'!E5:E10) | F6: ='Historical Actuals'!F11-SUM('Historical Actuals'!F5:F10) | G6: ='Historical Actuals'!G11-SUM('Historical Actuals'!G5:G10) | H6: ='Historical Actuals'!H11-SUM('Historical Actuals'!H5:H10) | I6: ='Historical Actuals'!I11-SUM('Historical Actuals'!I5:I10)
A9: CHECK_050 — Historical: sum of quarters = fiscal year (REV_370)
B10: FY2025 | C10: FY2026
A11: Variance ($mm), should be exactly 0 | B11: ='Historical Actuals'!K11-SUM('Historical Actuals'!B11:E11) | C11: ='Historical Actuals'!L11-SUM('Historical Actuals'!F11:I11)
A14: Forecast: six-stream sum = Total revenue (Revenue Forecast tab)
A15: Period | B15: FY27_Q1 | C15: FY27_Q2 | D15: FY27_Q3 | E15: FY27_Q4 | F15: FY28_Q1 | G15: FY28_Q2 | H15: FY28_Q3 | I15: FY28_Q4
A16: Variance ($mm), should be exactly 0 (true by construction - SUM formula) | B16: ='Revenue Forecast'!B35-SUM('Revenue Forecast'!B29:B34) | C16: ='Revenue Forecast'!C35-SUM('Revenue Forecast'!C29:C34) | D16: ='Revenue Forecast'!D35-SUM('Revenue Forecast'!D29:D34) | E16: ='Revenue Forecast'!E35-SUM('Revenue Forecast'!E29:E34) | F16: ='Revenue Forecast'!F35-SUM('Revenue Forecast'!F29:F34) | G16: ='Revenue Forecast'!G35-SUM('Revenue Forecast'!G29:G34) | H16: ='Revenue Forecast'!H35-SUM('Revenue Forecast'!H29:H34) | I16: ='Revenue Forecast'!I35-SUM('Revenue Forecast'!I29:I34)
A19: Forecast: sum of quarters = fiscal year (Revenue Forecast tab)
B20: FY2027 | C20: FY2028
A21: Variance ($mm), should be exactly 0 (true by construction) | B21: ='Revenue Forecast'!K35-SUM('Revenue Forecast'!B35:E35) | C21: ='Revenue Forecast'!L35-SUM('Revenue Forecast'!F35:I35)
A24: Scenario-switch integrity: Selected scenario matches Control Panel
A25: Driver | B25: Selected value | C25: Expected range check
A26: OCI growth % FY27 | B26: ='Scenario Assumptions'!I5 | C26: =IF(AND(B26>=MIN('Scenario Assumptions'!C5:H5),B26<=MAX('Scenario Assumptions'!C5:H5)),"OK - within bear-to-bull range","CHECK")
A27: Applications growth % FY27 | B27: ='Scenario Assumptions'!I7 | C27: =IF(AND(B27>=MIN('Scenario Assumptions'!C7:H7),B27<=MAX('Scenario Assumptions'!C7:H7)),"OK - within bear-to-bull range","CHECK")
A28: GAAP gross margin % FY27 | B28: ='Scenario Assumptions'!I11 | C28: =IF(AND(B28>=MIN('Scenario Assumptions'!C11:H11),B28<=MAX('Scenario Assumptions'!C11:H11)),"OK - within bear-to-bull range","CHECK")
A29: Non-GAAP operating margin % FY27 | B29: ='Scenario Assumptions'!I13 | C29: =IF(AND(B29>=MIN('Scenario Assumptions'!C13:H13),B29<=MAX('Scenario Assumptions'!C13:H13)),"OK - within bear-to-bull range","CHECK")
A32: Note
A33: This Checks tab covers what Gate 10's minimal scope actually builds: revenue-stream additivity and quarter-to-FY ties (historical and forecast), plus a scenario-switch sanity check. It does NOT yet include balance-sheet ties, cash-flow ties, or the full GAAP/non-GAAP bridge check (CHECK_090) - those require the debt/lease/capex mechanics that are Gate 12 (full build) scope. Gate 11 (model checks) should expand this tab before Gate 12 adds the balance-sheet and cash-flow schedules.
A36: CHECK_090 — GAAP/non-GAAP bridge: (Non-GAAP OI - GAAP OI) - (SBC + Amort + Acq/Restructuring)
A37: Period | B37: FY25_Q1 | C37: FY25_Q2 | D37: FY25_Q3 | E37: FY25_Q4 | F37: FY26_Q1 | G37: FY26_Q2 | H37: FY26_Q3 | I37: FY26_Q4
A38: Variance ($mm), should be ~0 (rounding tolerance $1mm) | B38: =('Historical Actuals'!B16-'Historical Actuals'!B15)-('Historical Actuals'!B25+'Historical Actuals'!B24+'Historical Actuals'!B26) | C38: =('Historical Actuals'!C16-'Historical Actuals'!C15)-('Historical Actuals'!C25+'Historical Actuals'!C24+'Historical Actuals'!C26) | D38: =('Historical Actuals'!D16-'Historical Actuals'!D15)-('Historical Actuals'!D25+'Historical Actuals'!D24+'Historical Actuals'!D26) | E38: =('Historical Actuals'!E16-'Historical Actuals'!E15)-('Historical Actuals'!E25+'Historical Actuals'!E24+'Historical Actuals'!E26) | F38: =('Historical Actuals'!F16-'Historical Actuals'!F15)-('Historical Actuals'!F25+'Historical Actuals'!F24+'Historical Actuals'!F26) | G38: =('Historical Actuals'!G16-'Historical Actuals'!G15)-('Historical Actuals'!G25+'Historical Actuals'!G24+'Historical Actuals'!G26) | H38: =('Historical Actuals'!H16-'Historical Actuals'!H15)-('Historical Actuals'!H25+'Historical Actuals'!H24+'Historical Actuals'!H26) | I38: =('Historical Actuals'!I16-'Historical Actuals'!I15)-('Historical Actuals'!I25+'Historical Actuals'!I24+'Historical Actuals'!I26)
A40: Note: this re-derives the GAAP/non-GAAP bridge from filed reconciling items (OPEX_040/050/060/065/070) independently of how PROF_030 was originally extracted (reported directly from the release), so it is a genuine second-source check, not a tautology. Ties within $1mm rounding across all 8 historical quarters. Forecast tab does not model these reconciling items yet (Gate 12) so this check is historical-only.
A43: CHECK_080 — Debt roll-forward: Beginning + Implied net issuance = Ending
B44: FY2027 | C44: FY2028
A45: Variance ($mm), should be exactly 0 (net issuance is defined as the plug, so this is true by construction — documents the identity, not an independent finding) | B45: ='Debt, Leases & Cash'!$B$5+'Debt, Leases & Cash'!K8-'Debt, Leases & Cash'!K6 | C45: ='Debt, Leases & Cash'!K6+'Debt, Leases & Cash'!L8-'Debt, Leases & Cash'!L6
A48: CHECK_100 — Cash tie: Beginning + Implied OCF − Net cash capex + Net debt issuance = Ending
B49: FY2027 | C49: FY2028
A50: Variance ($mm), should be exactly 0 (OCF is solved as this identity's plug — true by construction, documents the identity) | B50: ='Debt, Leases & Cash'!$B$18+'Cash Flow & Returns'!K13-'Cash Flow & Returns'!K7+'Debt, Leases & Cash'!K8-'Debt, Leases & Cash'!K19 | C50: ='Debt, Leases & Cash'!K19+'Cash Flow & Returns'!L13-'Cash Flow & Returns'!L7+'Debt, Leases & Cash'!L8-'Debt, Leases & Cash'!L19
A53: Note (Gate 12)
A54: CHECK_080 and CHECK_100 are true by construction (the model solves for the plug that makes them tie), so a passing result confirms the formulas are wired correctly, not that the underlying forecast is realistic — that judgment lives in whether the implied OCF and net debt issuance levels look plausible against Oracle's own guidance and history, which is a Gate 13 valuation-interpretation question, not a mechanical check.
